Workbook

Sheet Executive Summary
B2: SITE SELECTION · COVINGTON, KENTON COUNTY KY | I2: Prepared for the Board of Directors
B3: PUPS PUB COVINGTON | I3: Data as of 2 August 2026
B4: The Tail Chase List — every commercial parcel in the city, scored and ranked | I4: Kenton County PVA · LINK-GIS · LoopNet
B7: HOW THE FIELD WAS NARROWED
B9: 16,103 | D9: 384 | F9: 337 | H9: 328 | J9: 25
B10: Parcels in Covington | D10: Pass use & size screen | F10: Privately held | H10: Fully scored | J10: Drive-by shortlist
B13: TOP 15 TAIL CHASE TARGETS | I13: Score = factor points x scoped multipliers (v8) — see Scoring Method
A15: # | B15: Address | C15: Owner of record | D15: Current use | E15: Lot AC | F15: Bldg SF | G15: Yard SF | H15: Mi | I15: Neighborhood | J15: Est. rent | K15: Score
A16: 1 | B16: 209 JOHNSON ST | C16: RICHMOND RODNEY C TRUSTEE | D16: SMALL SHOP | E16: 0.3 | F16: 3000 | G16: 9900 | H16: 0.13 | I16: Botany Hills / Riverfront West | J16: $2,750/mo | K16: 82.3
A17: 2 | B17: 401-419 GREENUP ST | C17: RP PROP OZ LLC | D17: OTHER RETAIL | E17: 0.46 | F17: 1325 | G17: 10650 | H17: 0.26 | I17: Central Business District | J17: $1,215/mo | K17: 78.8
A18: 3 | B18: 409 MAIN ST | C18: SMITH HOLDING CO INC | D18: AUTO SERVICE/REPAIR | E18: 1.01 | F18: 14720 | G18: 27500 | H18: 0.1 | I18: MainStrasse | J18: $13,493/mo | K18: 78.6
A19: 4 | B19: 805 RUSSELL ST | C19: SEMINARY SQUARE II LLC | D19: GARAGE/PARKING SPACE | E19: 0.71 | G19: 30375 | H19: 0.22 | I19: MainStrasse | J19: — | K19: 78.5
A20: 5 | B20: 248 W PIKE ST | C20: CLAYPOOL PROPERTIES LLC | D20: WHSE DISTRIBUTION | E20: 0.87 | F20: 22064 | G20: 13300 | H20: 0.25 | I20: MainStrasse | J20: $20,225/mo | K20: 78.1
A21: 6 | B21: 409 W 4TH ST | C21: SMITH HOLDING CO INC | D21: AUTO SERVICE/REPAIR | E21: 0.48 | F21: 9000 | G21: 9650 | H21: 0.13 | I21: Botany Hills / Riverfront West | J21: $8,250/mo | K21: 77.5
A22: 7 | B22: 325 GREENUP ST | C22: BUTT LLC | D22: PAVED LOT | E22: 0.34 | F22: 2891 | G22: 14400 | H22: 0.22 | I22: Central Business District | J22: $2,650/mo | K22: 77.1
A23: 8 | B23: 620 W 5TH ST | C23: SKYLIGHT CINCINNATI HOLDING | D23: PAVED LOT | E23: 0.77 | G23: 33200 | H23: 0.18 | I23: MainStrasse | J23: — | K23: 75.5
A24: 9 | B24: 617 HINDE ST | C24: GABE HOLDINGS LLC | D24: SMALL SHOP | E24: 0.75 | G24: 30400 | H24: 0.72 | I24: Lewisburg | J24: — | K24: 74.7
A25: 10 | B25: 423 SCOTT ST | C25: DECASTRO MANAGEMENT LLC | D25: AUTO SERVICE/REPAIR | E25: 0.83 | F25: 17586 | G25: 17825 | H25: 0.18 | I25: Central Business District | J25: $16,120/mo | K25: 74.5
A26: 11 | B26: 101 W 6TH ST | C26: DIOCESE OF COVINGTON | D26: PAVED LOT | E26: 0.46 | G26: 19775 | H26: 0.06 | I26: Central Business District | J26: — | K26: 74.4
A27: 12 | B27: 102 8TH ST W | C27: PIKE PARTNERS LLC | D27: PAVED LOT | E27: 0.55 | G27: 23550 | H27: 0.17 | I27: Central Business District | J27: — | K27: 74.4
A28: 13 | B28: 601 SCOTT ST | C28: 608 MADISON LLC | D28: LAND/W MISCELLANEOUS IMPROVEMENT | E28: 0.52 | G28: 21625 | H28: 0.1 | I28: Central Business District | J28: — | K28: 74.4
A29: 14 | B29: 16 W 9TH ST | C29: BLUE BRIDGE LLC | D29: WHSE DISTRIBUTION | E29: 0.78 | F29: 31448 | G29: 12025 | H29: 0.18 | I29: Central Business District | J29: $28,827/mo | K29: 74
A30: 15 | B30: 305 W PIKE ST | C30: DUPONT VENTURES LLC | D30: RETAIL W/APARTMENTS | E30: 0.5 | F30: 4878 | G30: 7875 | H30: 0.35 | I30: MainStrasse | J30: $4,472/mo | K30: 72.7
B33: WHAT THE DATA SAYS
B35: ▸ Location and convertibility drive the ranking.
B36: The two strongest predictors of owner field ratings are distance to a walkable district (26 pts) and whether the shell can actually be opened up (20 pts). Both validated positively against 23 site visits.
B39: ▸ Chain-occupied pads look good on paper and are not obtainable.
B40: 46 parcels are held by a national brand or a net-lease investor. They score well physically and were rated 1–4 by the owner. An availability multiplier now pushes them out of contention.
B43: ▸ Usable yard is far smaller than lot arithmetic suggests.
B44: Measuring open space geometrically — and deleting any strip under 20 ft wide — cut apparent outdoor area by half or more on tight downtown parcels, and to zero on several.
B47: ▸ Oversized parcels are capped by design.
B48: Nothing above 1.25 acres reaches the top half of the list. The largest candidates remain visible but carry a 0.65 multiplier reflecting cost and complexity a single venue cannot absorb.
B51: WHAT THIS MODEL DOES NOT KNOW
B53: • Rent is assumed, not quoted — $11/SF gross against an $11,000/month target. No public Covington lease comps exist; every figure needs broker confirmation.
B56: • Crime is partly estimated — 5 of 14 neighbourhoods carry a NeighborhoodScout-sourced ranking; the remainder are judgment calls, flagged in the Scoring Method tab.
... B62: • Building size is mixed-source — LoopNet gross area where available, otherwise a single-storey footprint from GIS geometry, which understates multi-storey buildings.
A64: • Flood is now FEMA-sourced — NFHL zones joined 2 Aug 2026 for all 328 parcels (296 X · 22 levee-protected X · 7 shaded X · 3 AE). The 5/4/3.5/0 sub-band split is an owner-approved weighting decision, not a FEMA designation.
A65: • Zoning now scores — v7 multiplier (1.0/0.9/0.7/0.5/0.3 by NDC bar-status tier, owner-approved 2 Aug 2026) discounts Location and Convertibility only. 422 Russell falls #1→#45 (TUR: bars prohibited; restaurant/microbrewery alt-paths remain). New #1: 401-419 Greenup St (DTC). SU parcels provisional pending corner-lot check.
A66: • Model v8 (2 Aug 2026): multipliers are factor-scoped (availability -> location/building/convertibility; lot-size -> yard/building/convertibility; zoning -> location/convertibility). Crime/flood/environmental immune. 17 LoopNet building-SF corrections applied (157/328 verified). Compare ranks, not raw scores, across model versions. | B66: Model agreement with owner field ratings: r = +0.71 across 23 rated parcels.

Sheet Tail Chase List
A1: Rank | B1: Parcel ID | C1: Address | D1: Owner Name | E1: Mailing Address | F1: Mail City | G1: Mail ST | H1: Current Use | I1: Lot SF | J1: Lot Acres | K1: Perimeter FT | L1: Compactness | M1: Lot Band | N1: Structure Tier | O1: Compact Band | P1: Env Risk | Q1: Absentee Tier | R1: Owner Class | S1: Portfolio | T1: Site Fit | U1: Readiness | V1: Combined | W1: Building SF | X1: Flood Zone (FEMA NFHL) | Y1: Outdoor SF | Z1: Coverage % | AA1: Parking Est | AB1: Market Status | AC1: LoopNet Lot AC | AD1: Lot Variance | AE1: Bldg Fit Band | AF1: Verified Fit | AG1: Verified Combined | AH1: Data Source | AI1: Lat | AJ1: Lon | AK1: Mi to MainStrasse | AL1: Mi to Roebling Pt | AM1: Mi to Cincy CBD | AN1: Mi to Core | AO1: Location Band | AP1: Convertibility | AQ1: Outdoor Band | AR1: Crime Risk | AS1: Verified Fit v2 | AT1: Verified Combined v2 | AU1: Neighborhood | AV1: Crime Index | AW1: Crime Source | AX1: Crime Band | AY1: Fit v3 | AZ1: COMBINED v3 | BA1: Availability Class | BB1: Avail Multiplier | BC1: Lot Size Class | BD1: Lot Multiplier | BE1: Fit (raw factor sum) | BF1: CHASE SCORE v8 | BG1: Budget Fit @ $11k | BH1: NDC District | BI1: District Name | BJ1: HP Overlay | BK1: 12th St Corridor | BL1: NDC Bar Status | BM1: Zoning Mult
A2: 1 | B2: 054-22-40-001.01 | C2: 1206 CHESAPEAKE ST | D2: KIRN RONALD C & MELISSA | E2: 408 OLIVIA LN | F2: FT WRIGHT | G2: KY | H2: AUTO SERVICE/REPAIR | I2: 22126 | J2: =I2/43560 | K2: 595 | L2: =I2/(K2^2) | M2: Ideal 18-32k | N2: A | O2: Compact >=.055 | P2: Moderate | Q2: Out-of-city KY | R2: Individual | S2: 2 | T2: =INDEX('Scoring Method'!$B$6:$B$9,MATCH(M2,'Scoring Method'!$A$6:$A$9,0))+INDEX('Scoring Method'!$B$12:$B$16,MATCH(N2,'Scoring Method'!$A$12:$A$16,0))+INDEX('Scoring Method'!$B$19:$B$22,MATCH(O2,'Scoring Method'!$A$19:$A$22,0))+INDEX('Scoring Method'!$B$25:$B$27,MATCH(P2,'Scoring Method'!$A$25:$A$27,0)) | U2: =(INDEX('Scoring Method'!$B$30:$B$33,MATCH(Q2,'Scoring Method'!$A$30:$A$33,0))+INDEX('Scoring Method'!$B$36:$B$42,MATCH(R2,'Scoring Method'!$A$36:$A$42,0))+INDEX('Scoring Method'!$B$45:$B$47,MATCH(IF(S2=1,"1",IF(S2=2,"2","3+")),'Scoring Method'!$A$45:$A$47,0)))/90*100 | V2: =T2*U2/100 | W2: 5000 | X2: X (minimal hazard) | Y2: 15000 | Z2: =W2/I2 | AA2: =MAX(0,(Y2-5000)/300) | AC2: 0.51 | AD2: ok | AE2: Large 4-6k | AF2: =INDEX('Scoring Method'!$B$63:$B$71,MATCH(AE2,'Scoring Method'!$A$63:$A$71,0))+INDEX('Scoring Method'!$B$75:$B$79,MATCH("Ample >=15k",'Scoring Method'!$A$75:$A$79,0))+INDEX('Scoring Method'!$B$343:$B$347,MATCH(X2,'Scoring Method'!$A$343:$A$347,0))+INDEX('Scoring Method'!$B$25:$B$27,MATCH(P2,'Scoring Method'!$A$25:$A$27,0)) | AG2: =AF2*U2/100 | AH2: LINK-GIS + LoopNet | AI2: 39.07696 | AJ2: -84.51056 | AK2: 0.65 | AL2: 0.97 | AM2: 1.7 | AN2: 0.49 | AO2: Near 0.35-0.75mi | AP2: Open span | AQ2: Ample >=15k | AS2: =ROUND(INDEX('Scoring Method'!$B$63:$B$70,MATCH(AE2,'Scoring Method'!$A$63:$A$70,0))*0.625+INDEX('Scoring Method'!$B$105:$B$113,MATCH(AP2,'Scoring Method'!$A$105:$A$113,0))+INDEX('Scoring Method'!$B$74:$B$78,MATCH(AQ2,'Scoring Method'!$A$74:$A$78,0))*0.6667+INDEX('Scoring Method'!$B$96:$B$101,MATCH(AO2,'Scoring Method'!$A$96:$A$101,0))+INDEX('Scoring Method'!$B$343:$B$347,MATCH(X2,'Scoring Method'!$A$343:$A$347,0))*0.3333+INDEX('Scoring Method'!$B$25:$B$27,MATCH(P2,'Scoring Method'!$A$25:$A$27,0))*0.3333,1) | AT2: =AS2*U2/100 | AU2: Old Seminary Square | AV2: 35 | AW2: ESTIMATED | AX2: Elevated 35-44 | AY2: =ROUND(INDEX('Scoring Method'!$B$132:$B$140,MATCH(AE2,'Scoring Method'!$A$132:$A$140,0))+INDEX('Scoring Method'!$B$144:$B$152,MATCH(AP2,'Scoring Method'!$A$144:$A$152,0))+INDEX('Scoring Method'!$B$156:$B$160,MATCH(AQ2,'Scoring Method'!$A$156:$A$160,0))+INDEX('Scoring Method'!$B$164:$B$169,MATCH(AO2,'Scoring Method'!$A$164:$A$169,0))+INDEX('Scoring Method'!$B$173:$B$178,MATCH(AX2,'Scoring Method'!$A$173:$A$178,0))+INDEX('Scoring Method'!$B$349:$B$353,MATCH(X2,'Scoring Method'!$A$349:$A$353,0))+INDEX('Scoring Method'!$B$188:$B$190,MATCH(P2,'Scoring Method'!$A$188:$A$190,0)),1) | AZ2: =AY2*U2/100 | BA2: No chain signal | BB2: 1 | BC2: Right-sized 0.35-0.75 AC | BD2: 1 | BE2: =ROUND(INDEX('Scoring Method'!$B$268:$B$276,MATCH(AE2,'Scoring Method'!$A$268:$A$276,0))+INDEX('Scoring Method'!$B$280:$B$288,MATCH(AP2,'Scoring Method'!$A$280:$A$288,0))+INDEX('Scoring Method'!$B$292:$B$296,MATCH(AQ2,'Scoring Method'!$A$292:$A$296,0))+INDEX('Scoring Method'!$B$300:$B$305,MATCH(AO2,'Scoring Method'!$A$300:$A$305,0))+INDEX('Scoring Method'!$B$309:$B$314,MATCH(AX2,'Scoring Method'!$A$309:$A$314,0))+INDEX('Scoring Method'!$B$337:$B$341,MATCH(X2,'Scoring Method'!$A$337:$A$341,0))+INDEX('Scoring Method'!$B$324:$B$326,MATCH(P2,'Scoring Method'!$A$324:$A$326,0)),1) | BF2: =ROUND(INDEX('Scoring Method'!$B$268:$B$276,MATCH(AE2,'Scoring Method'!$A$268:$A$276,0))*BB2*BD2+INDEX('Scoring Method'!$B$280:$B$288,MATCH(AP2,'Scoring Method'!$A$280:$A$288,0))*BM2*BB2*BD2+INDEX('Scoring Method'!$B$292:$B$296,MATCH(AQ2,'Scoring Method'!$A$292:$A$296,0))*BD2+INDEX('Scoring Method'!$B$300:$B$305,MATCH(AO2,'Scoring Method'!$A$300:$A$305,0))*BM2*BB2+INDEX('Scoring Method'!$B$309:$B$314,MATCH(AX2,'Scoring Method'!$A$309:$A$314,0))+INDEX('Scoring Method'!$B$337:$B$341,MATCH(X2,'Scoring Method'!$A$337:$A$341,0))+INDEX('Scoring Method'!$B$324:$B$326,MATCH(P2,'Scoring Method'!$A$324:$A$326,0)),1) | BG2: Fits (~$4,583/mo) | BH2: LI (TS) | BI2: Limited Industrial | BK2: Yes | BL2: Bar prohibited, alt-path | BM2: =INDEX('Scoring Method'!$B$358:$B$363,MATCH(BL2,'Scoring Method'!$A$358:$A$363,0))
A3: 2 | B3: 055-14-12-003.00 | C3: 1901 MADISON AVE | D3: NEW HORIZON PROPERTIES LLC | E3: 3000 READING RD | F3: CINCINNATI | G3: OH | H3: AUTO SERVICE/REPAIR | I3: 18667 | J3: =I3/43560 | K3: 658.2 | L3: =I3/(K3^2) | M3: Ideal 18-32k | N3: A | O3: Elongated .035-.045 | P3: Moderate | Q3: Out-of-state | R3: Passive vehicle | S3: 2 | T3: =INDEX('Scoring Method'!$B$6:$B$9,MATCH(M3,'Scoring Method'!$A$6:$A$9,0))+INDEX('Scoring Method'!$B$12:$B$16,MATCH(N3,'Scoring Method'!$A$12:$A$16,0))+INDEX('Scoring Method'!$B$19:$B$22,MATCH(O3,'Scoring Method'!$A$19:$A$22,0))+INDEX('Scoring Method'!$B$25:$B$27,MATCH(P3,'Scoring Method'!$A$25:$A$27,0)) | U3: =(INDEX('Scoring Method'!$B$30:$B$33,MATCH(Q3,'Scoring Method'!$A$30:$A$33,0))+INDEX('Scoring Method'!$B$36:$B$42,MATCH(R3,'Scoring Method'!$A$36:$A$42,0))+INDEX('Scoring Method'!$B$45:$B$47,MATCH(IF(S3=1,"1",IF(S3=2,"2","3+")),'Scoring Method'!$A$45:$A$47,0)))/90*100 | V3: =T3*U3/100 | W3: 1260 | X3: X (minimal hazard) | Y3: 15475 | Z3: =W3/I3 | AA3: =MAX(0,(Y3-5000)/300) | AC3: 0.43 | AD3: ok | AE3: Below 1.2-1.5k | AF3: =INDEX('Scoring Method'!$B$63:$B$71,MATCH(AE3,'Scoring Method'!$A$63:$A$71,0))+INDEX('Scoring Method'!$B$75:$B$79,MATCH("Ample >=15k",'Scoring Method'!$A$75:$A$79,0))+INDEX('Scoring Method'!$B$343:$B$347,MATCH(X3,'Scoring Method'!$A$343:$A$347,0))+INDEX('Scoring Method'!$B$25:$B$27,MATCH(P3,'Scoring Method'!$A$25:$A$27,0)) | AG3: =AF3*U3/100 | AH3: LINK-GIS + LoopNet | AI3: 39.06755 | AJ3: -84.50646 | AK3: 1.32 | AL3: 1.61 | AM3: 2.37 | AN3: 1.16 | AO3: Fringe 0.75-1.25mi | AP3: Open span | AQ3: Ample >=15k | AS3: =ROUND(INDEX('Scoring Method'!$B$63:$B$70,MATCH(AE3,'Scoring Method'!$A$63:$A$70,0))*0.625+INDEX('Scoring Method'!$B$105:$B$113,MATCH(AP3,'Scoring Method'!$A$105:$A$113,0))+INDEX('Scoring Method'!$B$74:$B$78,MATCH(AQ3,'Scoring Method'!$A$74:$A$78,0))*0.6667+INDEX('Scoring Method'!$B$96:$B$101,MATCH(AO3,'Scoring Method'!$A$96:$A$101,0))+INDEX('Scoring Method'!$B$343:$B$347,MATCH(X3,'Scoring Method'!$A$343:$A$347,0))*0.3333+INDEX('Scoring Method'!$B$25:$B$27,MATCH(P3,'Scoring Method'!$A$25:$A$27,0))*0.3333,1) | AT3: =AS3*U3/100 | AU3: Levassor Park | AV3: 42 | AW3: ESTIMATED | AX3: Elevated 35-44 | AY3: =ROUND(INDEX('Scoring Method'!$B$132:$B$140,MATCH(AE3,'Scoring Method'!$A$132:$A$140,0))+INDEX('Scoring Method'!$B$144:$B$152,MATCH(AP3,'Scoring Method'!$A$144:$A$152,0))+INDEX('Scoring Method'!$B$156:$B$160,MATCH(AQ3,'Scoring Method'!$A$156:$A$160,0))+INDEX('Scoring Method'!$B$164:$B$169,MATCH(AO3,'Scoring Method'!$A$164:$A$169,0))+INDEX('Scoring Method'!$B$173:$B$178,MATCH(AX3,'Scoring Method'!$A$173:$A$178,0))+INDEX('Scoring Method'!$B$349:$B$353,MATCH(X3,'Scoring Method'!$A$349:$A$353,0))+INDEX('Scoring Method'!$B$188:$B$190,MATCH(P3,'Scoring Method'!$A$188:$A$190,0)),1) | AZ3: =AY3*U3/100 | BA3: No chain signal | BB3: 1 | BC3: Right-sized 0.35-0.75 AC | BD3: 1 | BE3: =ROUND(INDEX('Scoring Method'!$B$268:$B$276,MATCH(AE3,'Scoring Method'!$A$268:$A$276,0))+INDEX('Scoring Method'!$B$280:$B$288,MATCH(AP3,'Scoring Method'!$A$280:$A$288,0))+INDEX('Scoring Method'!$B$292:$B$296,MATCH(AQ3,'Scoring Method'!$A$292:$A$296,0))+INDEX('Scoring Method'!$B$300:$B$305,MATCH(AO3,'Scoring Method'!$A$300:$A$305,0))+INDEX('Scoring Method'!$B$309:$B$314,MATCH(AX3,'Scoring Method'!$A$309:$A$314,0))+INDEX('Scoring Method'!$B$337:$B$341,MATCH(X3,'Scoring Method'!$A$337:$A$341,0))+INDEX('Scoring Method'!$B$324:$B$326,MATCH(P3,'Scoring Method'!$A$324:$A$326,0)),1) | BF3: =ROUND(INDEX('Scoring Method'!$B$268:$B$276,MATCH(AE3,'Scoring Method'!$A$268:$A$276,0))*BB3*BD3+INDEX('Scoring Method'!$B$280:$B$288,MATCH(AP3,'Scoring Method'!$A$280:$A$288,0))*BM3*BB3*BD3+INDEX('Scoring Method'!$B$292:$B$296,MATCH(AQ3,'Scoring Method'!$A$292:$A$296,0))*BD3+INDEX('Scoring Method'!$B$300:$B$305,MATCH(AO3,'Scoring Method'!$A$300:$A$305,0))*BM3*BB3+INDEX('Scoring Method'!$B$309:$B$314,MATCH(AX3,'Scoring Method'!$A$309:$A$314,0))+INDEX('Scoring Method'!$B$337:$B$341,MATCH(X3,'Scoring Method'!$A$337:$A$341,0))+INDEX('Scoring Method'!$B$324:$B$326,MATCH(P3,'Scoring Method'!$A$324:$A$326,0)),1) | BG3: Fits (~$1,155/mo) | BH3: AUC | BI3: Auto-Urban Commercial | BL3: Bar permitted | BM3: =INDEX('Scoring Method'!$B$358:$B$363,MATCH(BL3,'Scoring Method'!$A$358:$A$363,0))
A4: 3 | B4: 040-43-07-001.01 | C4: 501 W 4TH ST | D4: DAYAN MICHELLE & CHEN | E4: 2424 RIDGE RD | F4: ROCKWALL | G4: TX | H4: FAST FOOD-DRIVE THRU REST | I4: 23325 | J4: =I4/43560 | K4: 645 | L4: =I4/(K4^2) | M4: Ideal 18-32k | N4: C | O4: Compact >=.055 | P4: Low | Q4: Out-of-state | R4: Individual | S4: 1 | T4: =INDEX('Scoring Method'!$B$6:$B$9,MATCH(M4,'Scoring Method'!$A$6:$A$9,0))+INDEX('Scoring Method'!$B$12:$B$16,MATCH(N4,'Scoring Method'!$A$12:$A$16,0))+INDEX('Scoring Method'!$B$19:$B$22,MATCH(O4,'Scoring Method'!$A$19:$A$22,0))+INDEX('Scoring Method'!$B$25:$B$27,MATCH(P4,'Scoring Method'!$A$25:$A$27,0)) | U4: =(INDEX('Scoring Method'!$B$30:$B$33,MATCH(Q4,'Scoring Method'!$A$30:$A$33,0))+INDEX('Scoring Method'!$B$36:$B$42,MATCH(R4,'Scoring Method'!$A$36:$A$42,0))+INDEX('Scoring Method'!$B$45:$B$47,MATCH(IF(S4=1,"1",IF(S4=2,"2","3+")),'Scoring Method'!$A$45:$A$47,0)))/90*100 | V4: =T4*U4/100 | X4: X (minimal hazard) | Y4: 20300 | AC4: 0.54 | AD4: ok | AE4: No building | AF4: =INDEX('Scoring Method'!$B$63:$B$71,MATCH(AE4,'Scoring Method'!$A$63:$A$71,0))+INDEX('Scoring Method'!$B$75:$B$79,MATCH("Ample >=15k",'Scoring Method'!$A$75:$A$79,0))+INDEX('Scoring Method'!$B$343:$B$347,MATCH(X4,'Scoring Method'!$A$343:$A$347,0))+INDEX('Scoring Method'!$B$25:$B$27,MATCH(P4,'Scoring Method'!$A$25:$A$27,0)) | AG4: =AF4*U4/100 | AH4: LINK-GIS + LoopNet | AI4: 39.08608 | AJ4: -84.51918 | AK4: 0.14 | AL4: 0.67 | AM4: 1.13 | AN4: 0.14 | AO4: Core <=0.35mi | AP4: Built-out kitchen | AQ4: Ample >=15k | AS4: =ROUND(INDEX('Scoring Method'!$B$63:$B$70,MATCH(AE4,'Scoring Method'!$A$63:$A$70,0))*0.625+INDEX('Scoring Method'!$B$105:$B$113,MATCH(AP4,'Scoring Method'!$A$105:$A$113,0))+INDEX('Scoring Method'!$B$74:$B$78,MATCH(AQ4,'Scoring Method'!$A$74:$A$78,0))*0.6667+INDEX('Scoring Method'!$B$96:$B$101,MATCH(AO4,'Scoring Method'!$A$96:$A$101,0))+INDEX('Scoring Method'!$B$343:$B$347,MATCH(X4,'Scoring Method'!$A$343:$A$347,0))*0.3333+INDEX('Scoring Method'!$B$25:$B$27,MATCH(P4,'Scoring Method'!$A$25:$A$27,0))*0.3333,1) | AT4: =AS4*U4/100 | AU4: Botany Hills / Riverfront West | AV4: 45 | AW4: ESTIMATED | AX4: Mixed 45-59 | AY4: =ROUND(INDEX('Scoring Method'!$B$132:$B$140,MATCH(AE4,'Scoring Method'!$A$132:$A$140,0))+INDEX('Scoring Method'!$B$144:$B$152,MATCH(AP4,'Scoring Method'!$A$144:$A$152,0))+INDEX('Scoring Method'!$B$156:$B$160,MATCH(AQ4,'Scoring Method'!$A$156:$A$160,0))+INDEX('Scoring Method'!$B$164:$B$169,MATCH(AO4,'Scoring Method'!$A$164:$A$169,0))+INDEX('Scoring Method'!$B$173:$B$178,MATCH(AX4,'Scoring Method'!$A$173:$A$178,0))+INDEX('Scoring Method'!$B$349:$B$353,MATCH(X4,'Scoring Method'!$A$349:$A$353,0))+INDEX('Scoring Method'!$B$188:$B$190,MATCH(P4,'Scoring Method'!$A$188:$A$190,0)),1) | AZ4: =AY4*U4/100 | BA4: Chain format + local owner | BB4: 0.7 | BC4: Right-sized 0.35-0.75 AC | BD4: 1 | BE4: =ROUND(INDEX('Scoring Method'!$B$268:$B$276,MATCH(AE4,'Scoring Method'!$A$268:$A$276,0))+INDEX('Scoring Method'!$B$280:$B$288,MATCH(AP4,'Scoring Method'!$A$280:$A$288,0))+INDEX('Scoring Method'!$B$292:$B$296,MATCH(AQ4,'Scoring Method'!$A$292:$A$296,0))+INDEX('Scoring Method'!$B$300:$B$305,MATCH(AO4,'Scoring Method'!$A$300:$A$305,0))+INDEX('Scoring Method'!$B$309:$B$314,MATCH(AX4,'Scoring Method'!$A$309:$A$314,0))+INDEX('Scoring Method'!$B$337:$B$341,MATCH(X4,'Scoring Method'!$A$337:$A$341,0))+INDEX('Scoring Method'!$B$324:$B$326,MATCH(P4,'Scoring Method'!$A$324:$A$326,0)),1) | BF4: =ROUND(INDEX('Scoring Method'!$B$268:$B$276,MATCH(AE4,'Scoring Method'!$A$268:$A$276,0))*BB4*BD4+INDEX('Scoring Method'!$B$280:$B$288,MATCH(AP4,'Scoring Method'!$A$280:$A$288,0))*BM4*BB4*BD4+INDEX('Scoring Method'!$B$292:$B$296,MATCH(AQ4,'Scoring Method'!$A$292:$A$296,0))*BD4+INDEX('Scoring Method'!$B$300:$B$305,MATCH(AO4,'Scoring Method'!$A$300:$A$305,0))*BM4*BB4+INDEX('Scoring Method'!$B$309:$B$314,MATCH(AX4,'Scoring Method'!$A$309:$A$314,0))+INDEX('Scoring Method'!$B$337:$B$341,MATCH(X4,'Scoring Method'!$A$337:$A$341,0))+INDEX('Scoring Method'!$B$324:$B$326,MATCH(P4,'Scoring Method'!$A$324:$A$326,0)),1) | BH4: AUC | BI4: Auto-Urban Commercial | BL4: Bar permitted | BM4: =INDEX('Scoring Method'!$B$358:$B$363,MATCH(BL4,'Scoring Method'!$A$358:$A$363,0))
A5: 4 | B5: 054-23-13-001.00 | C5: 602 SCOTT ST | D5: CUMMINS THOMAS M & PATRICIA | E5: 3638 ROUND BOTTOM RD | F5: CINCINNATI | G5: OH | H5: FAST FOOD-DRIVE THRU REST | I5: 22010 | J5: =I5/43560 | K5: 612 | L5: =I5/(K5^2) | M5: Ideal 18-32k | N5: C | O5: Compact >=.055 | P5: Low | Q5: Out-of-state | R5: Individual | S5: 1 | T5: =INDEX('Scoring Method'!$B$6:$B$9,MATCH(M5,'Scoring Method'!$A$6:$A$9,0))+INDEX('Scoring Method'!$B$12:$B$16,MATCH(N5,'Scoring Method'!$A$12:$A$16,0))+INDEX('Scoring Method'!$B$19:$B$22,MATCH(O5,'Scoring Method'!$A$19:$A$22,0))+INDEX('Scoring Method'!$B$25:$B$27,MATCH(P5,'Scoring Method'!$A$25:$A$27,0)) | U5: =(INDEX('Scoring Method'!$B$30:$B$33,MATCH(Q5,'Scoring Method'!$A$30:$A$33,0))+INDEX('Scoring Method'!$B$36:$B$42,MATCH(R5,'Scoring Method'!$A$36:$A$42,0))+INDEX('Scoring Method'!$B$45:$B$47,MATCH(IF(S5=1,"1",IF(S5=2,"2","3+")),'Scoring Method'!$A$45:$A$47,0)))/90*100 | V5: =T5*U5/100 | W5: 2350 | X5: X (minimal hazard) | Y5: 16775 | Z5: =W5/I5 | AA5: =MAX(0,(Y5-5000)/300) | AC5: 0.51 | AD5: ok | AE5: Target 1.5-2.5k | AF5: =INDEX('Scoring Method'!$B$63:$B$71,MATCH(AE5,'Scoring Method'!$A$63:$A$71,0))+INDEX('Scoring Method'!$B$75:$B$79,MATCH("Ample >=15k",'Scoring Method'!$A$75:$A$79,0))+INDEX('Scoring Method'!$B$343:$B$347,MATCH(X5,'Scoring Method'!$A$343:$A$347,0))+INDEX('Scoring Method'!$B$25:$B$27,MATCH(P5,'Scoring Method'!$A$25:$A$27,0)) | AG5: =AF5*U5/100 | AH5: LINK-GIS + LoopNet | AI5: 39.08475 | AJ5: -84.50838 | AK5: 0.51 | AL5: 0.42 | AM5: 1.18 | AN5: 0.15 | AO5: Core <=0.35mi | AP5: Built-out kitchen | AQ5: Ample >=15k | AS5: =ROUND(INDEX('Scoring Method'!$B$63:$B$70,MATCH(AE5,'Scoring Method'!$A$63:$A$70,0))*0.625+INDEX('Scoring Method'!$B$105:$B$113,MATCH(AP5,'Scoring Method'!$A$105:$A$113,0))+INDEX('Scoring Method'!$B$74:$B$78,MATCH(AQ5,'Scoring Method'!$A$74:$A$78,0))*0.6667+INDEX('Scoring Method'!$B$96:$B$101,MATCH(AO5,'Scoring Method'!$A$96:$A$101,0))+INDEX('Scoring Method'!$B$343:$B$347,MATCH(X5,'Scoring Method'!$A$343:$A$347,0))*0.3333+INDEX('Scoring Method'!$B$25:$B$27,MATCH(P5,'Scoring Method'!$A$25:$A$27,0))*0.3333,1) | AT5: =AS5*U5/100 | AU5: Central Business District | AV5: 48 | AW5: ESTIMATED | AX5: Mixed 45-59 | AY5: =ROUND(INDEX('Scoring Method'!$B$132:$B$140,MATCH(AE5,'Scoring Method'!$A$132:$A$140,0))+INDEX('Scoring Method'!$B$144:$B$152,MATCH(AP5,'Scoring Method'!$A$144:$A$152,0))+INDEX('Scoring Method'!$B$156:$B$160,MATCH(AQ5,'Scoring Method'!$A$156:$A$160,0))+INDEX('Scoring Method'!$B$164:$B$169,MATCH(AO5,'Scoring Method'!$A$164:$A$169,0))+INDEX('Scoring Method'!$B$173:$B$178,MATCH(AX5,'Scoring Method'!$A$173:$A$178,0))+INDEX('Scoring Method'!$B$349:$B$353,MATCH(X5,'Scoring Method'!$A$349:$A$353,0))+INDEX('Scoring Method'!$B$188:$B$190,MATCH(P5,'Scoring Method'!$A$188:$A$190,0)),1) | AZ5: =AY5*U5/100 | BA5: Chain format + local owner | BB5: 0.7 | BC5: Right-sized 0.35-0.75 AC | BD5: 1 | BE5: =ROUND(INDEX('Scoring Method'!$B$268:$B$276,MATCH(AE5,'Scoring Method'!$A$268:$A$276,0))+INDEX('Scoring Method'!$B$280:$B$288,MATCH(AP5,'Scoring Method'!$A$280:$A$288,0))+INDEX('Scoring Method'!$B$292:$B$296,MATCH(AQ5,'Scoring Method'!$A$292:$A$296,0))+INDEX('Scoring Method'!$B$300:$B$305,MATCH(AO5,'Scoring Method'!$A$300:$A$305,0))+INDEX('Scoring Method'!$B$309:$B$314,MATCH(AX5,'Scoring Method'!$A$309:$A$314,0))+INDEX('Scoring Method'!$B$337:$B$341,MATCH(X5,'Scoring Method'!$A$337:$A$341,0))+INDEX('Scoring Method'!$B$324:$B$326,MATCH(P5,'Scoring Method'!$A$324:$A$326,0)),1) | BF5: =ROUND(INDEX('Scoring Method'!$B$268:$B$276,MATCH(AE5,'Scoring Method'!$A$268:$A$276,0))*BB5*BD5+INDEX('Scoring Method'!$B$280:$B$288,MATCH(AP5,'Scoring Method'!$A$280:$A$288,0))*BM5*BB5*BD5+INDEX('Scoring Method'!$B$292:$B$296,MATCH(AQ5,'Scoring Method'!$A$292:$A$296,0))*BD5+INDEX('Scoring Method'!$B$300:$B$305,MATCH(AO5,'Scoring Method'!$A$300:$A$305,0))*BM5*BB5+INDEX('Scoring Method'!$B$309:$B$314,MATCH(AX5,'Scoring Method'!$A$309:$A$314,0))+INDEX('Scoring Method'!$B$337:$B$341,MATCH(X5,'Scoring Method'!$A$337:$A$341,0))+INDEX('Scoring Method'!$B$324:$B$326,MATCH(P5,'Scoring Method'!$A$324:$A$326,0)),1) | BG5: Fits (~$2,154/mo) | BH5: DTC (HP) | BI5: Downtown Core | BJ5: HP | BL5: Bar permitted | BM5: =INDEX('Scoring Method'!$B$358:$B$363,MATCH(BL5,'Scoring Method'!$A$358:$A$363,0))
A6: 5 | B6: 054-24-03-004.00 | C6: 1041 MADISON AVE | D6: MURPHY & ROWDY ENTERPRISES LLC | E6: 915 W 8TH ST | F6: CINCINNATI | G6: OH | H6: MFG/ASSEMBLY 20000 SF OR LESS | I6: 20908 | J6: =I6/43560 | K6: 639.1 | L6: =I6/(K6^2) | M6: Ideal 18-32k | N6: A | O6: Regular .045-.055 | P6: Moderate | Q6: Out-of-state | R6: Passive vehicle | S6: 1 | T6: =INDEX('Scoring Method'!$B$6:$B$9,MATCH(M6,'Scoring Method'!$A$6:$A$9,0))+INDEX('Scoring Method'!$B$12:$B$16,MATCH(N6,'Scoring Method'!$A$12:$A$16,0))+INDEX('Scoring Method'!$B$19:$B$22,MATCH(O6,'Scoring Method'!$A$19:$A$22,0))+INDEX('Scoring Method'!$B$25:$B$27,MATCH(P6,'Scoring Method'!$A$25:$A$27,0)) | U6: =(INDEX('Scoring Method'!$B$30:$B$33,MATCH(Q6,'Scoring Method'!$A$30:$A$33,0))+INDEX('Scoring Method'!$B$36:$B$42,MATCH(R6,'Scoring Method'!$A$36:$A$42,0))+INDEX('Scoring Method'!$B$45:$B$47,MATCH(IF(S6=1,"1",IF(S6=2,"2","3+")),'Scoring Method'!$A$45:$A$47,0)))/90*100 | V6: =T6*U6/100 | W6: 14000 | X6: X (minimal hazard) | Y6: 3225 | Z6: =W6/I6 | AA6: =MAX(0,(Y6-5000)/300) | AC6: 0.44 | AD6: ok | AE6: Far oversize >12k | AF6: =INDEX('Scoring Method'!$B$63:$B$71,MATCH(AE6,'Scoring Method'!$A$63:$A$71,0))+INDEX('Scoring Method'!$B$75:$B$79,MATCH("Tight 2-5k",'Scoring Method'!$A$75:$A$79,0))+INDEX('Scoring Method'!$B$343:$B$347,MATCH(X6,'Scoring Method'!$A$343:$A$347,0))+INDEX('Scoring Method'!$B$25:$B$27,MATCH(P6,'Scoring Method'!$A$25:$A$27,0)) | AG6: =AF6*U6/100 | AH6: LINK-GIS + LoopNet | AI6: 39.07912 | AJ6: -84.50942 | AK6: 0.58 | AL6: 0.81 | AM6: 1.55 | AN6: 0.35 | AO6: Core <=0.35mi | AP6: Open span | AQ6: Tight 2-5k | AS6: =ROUND(INDEX('Scoring Method'!$B$63:$B$70,MATCH(AE6,'Scoring Method'!$A$63:$A$70,0))*0.625+INDEX('Scoring Method'!$B$105:$B$113,MATCH(AP6,'Scoring Method'!$A$105:$A$113,0))+INDEX('Scoring Method'!$B$74:$B$78,MATCH(AQ6,'Scoring Method'!$A$74:$A$78,0))*0.6667+INDEX('Scoring Method'!$B$96:$B$101,MATCH(AO6,'Scoring Method'!$A$96:$A$101,0))+INDEX('Scoring Method'!$B$343:$B$347,MATCH(X6,'Scoring Method'!$A$343:$A$347,0))*0.3333+INDEX('Scoring Method'!$B$25:$B$27,MATCH(P6,'Scoring Method'!$A$25:$A$27,0))*0.3333,1) | AT6: =AS6*U6/100 | AU6: Central Business District | AV6: 48 | AW6: ESTIMATED | AX6: Mixed 45-59 | AY6: =ROUND(INDEX('Scoring Method'!$B$132:$B$140,MATCH(AE6,'Scoring Method'!$A$132:$A$140,0))+INDEX('Scoring Method'!$B$144:$B$152,MATCH(AP6,'Scoring Method'!$A$144:$A$152,0))+INDEX('Scoring Method'!$B$156:$B$160,MATCH(AQ6,'Scoring Method'!$A$156:$A$160,0))+INDEX('Scoring Method'!$B$164:$B$169,MATCH(AO6,'Scoring Method'!$A$164:$A$169,0))+INDEX('Scoring Method'!$B$173:$B$178,MATCH(AX6,'Scoring Method'!$A$173:$A$178,0))+INDEX('Scoring Method'!$B$349:$B$353,MATCH(X6,'Scoring Method'!$A$349:$A$353,0))+INDEX('Scoring Method'!$B$188:$B$190,MATCH(P6,'Scoring Method'!$A$188:$A$190,0)),1) | AZ6: =AY6*U6/100 | BA6: No chain signal | BB6: 1 | BC6: Right-sized 0.35-0.75 AC | BD6: 1 | BE6: =ROUND(INDEX('Scoring Method'!$B$268:$B$276,MATCH(AE6,'Scoring Method'!$A$268:$A$276,0))+INDEX('Scoring Method'!$B$280:$B$288,MATCH(AP6,'Scoring Method'!$A$280:$A$288,0))+INDEX('Scoring Method'!$B$292:$B$296,MATCH(AQ6,'Scoring Method'!$A$292:$A$296,0))+INDEX('Scoring Method'!$B$300:$B$305,MATCH(AO6,'Scoring Method'!$A$300:$A$305,0))+INDEX('Scoring Method'!$B$309:$B$314,MATCH(AX6,'Scoring Method'!$A$309:$A$314,0))+INDEX('Scoring Method'!$B$337:$B$341,MATCH(X6,'Scoring Method'!$A$337:$A$341,0))+INDEX('Scoring Method'!$B$324:$B$326,MATCH(P6,'Scoring Method'!$A$324:$A$326,0)),1) | BF6: =ROUND(INDEX('Scoring Method'!$B$268:$B$276,MATCH(AE6,'Scoring Method'!$A$268:$A$276,0))*BB6*BD6+INDEX('Scoring Method'!$B$280:$B$288,MATCH(AP6,'Scoring Method'!$A$280:$A$288,0))*BM6*BB6*BD6+INDEX('Scoring Method'!$B$292:$B$296,MATCH(AQ6,'Scoring Method'!$A$292:$A$296,0))*BD6+INDEX('Scoring Method'!$B$300:$B$305,MATCH(AO6,'Scoring Method'!$A$300:$A$305,0))*BM6*BB6+INDEX('Scoring Method'!$B$309:$B$314,MATCH(AX6,'Scoring Method'!$A$309:$A$314,0))+INDEX('Scoring Method'!$B$337:$B$341,MATCH(X6,'Scoring Method'!$A$337:$A$341,0))+INDEX('Scoring Method'!$B$324:$B$326,MATCH(P6,'Scoring Method'!$A$324:$A$326,0)),1) | BG6: Over (~$12,833/mo) | BH6: DTC | BI6: Downtown Core | BL6: Bar permitted | BM6: =INDEX('Scoring Method'!$B$358:$B$363,MATCH(BL6,'Scoring Method'!$A$358:$A$363,0))
A7: 6 | B7: 056-31-09-002.00 | C7: 119 E 32ND ST | D7: MW & MW PROPERTIES INC | E7: PO BOX 15609 | F7: COVINGTON | G7: KY | H7: SMALL SHOP | I7: 19464 | J7: =I7/43560 | K7: 712.4 | L7: =I7/(K7^2) | M7: Ideal 18-32k | N7: A | O7: Elongated .035-.045 | P7: Low | Q7: Local absentee | R7: Passive vehicle | S7: 3 | T7: =INDEX('Scoring Method'!$B$6:$B$9,MATCH(M7,'Scoring Method'!$A$6:$A$9,0))+INDEX('Scoring Method'!$B$12:$B$16,MATCH(N7,'Scoring Method'!$A$12:$A$16,0))+INDEX('Scoring Method'!$B$19:$B$22,MATCH(O7,'Scoring Method'!$A$19:$A$22,0))+INDEX('Scoring Method'!$B$25:$B$27,MATCH(P7,'Scoring Method'!$A$25:$A$27,0)) | U7: =(INDEX('Scoring Method'!$B$30:$B$33,MATCH(Q7,'Scoring Method'!$A$30:$A$33,0))+INDEX('Scoring Method'!$B$36:$B$42,MATCH(R7,'Scoring Method'!$A$36:$A$42,0))+INDEX('Scoring Method'!$B$45:$B$47,MATCH(IF(S7=1,"1",IF(S7=2,"2","3+")),'Scoring Method'!$A$45:$A$47,0)))/90*100 | V7: =T7*U7/100 | W7: 5110 | X7: X (minimal hazard) | Y7: 10525 | Z7: =W7/I7 | AA7: =MAX(0,(Y7-5000)/300) | AC7: 0.45 | AD7: ok | AE7: Large 4-6k | AF7: =INDEX('Scoring Method'!$B$63:$B$71,MATCH(AE7,'Scoring Method'!$A$63:$A$71,0))+INDEX('Scoring Method'!$B$75:$B$79,MATCH("Good 8-15k",'Scoring Method'!$A$75:$A$79,0))+INDEX('Scoring Method'!$B$343:$B$347,MATCH(X7,'Scoring Method'!$A$343:$A$347,0))+INDEX('Scoring Method'!$B$25:$B$27,MATCH(P7,'Scoring Method'!$A$25:$A$27,0)) | AG7: =AF7*U7/100 | AH7: LINK-GIS + LoopNet | AI7: 39.05315 | AJ7: -84.5004 | AK7: 2.35 | AL7: 2.64 | AM7: 3.4 | AN7: 2.21 | AO7: Distant 2-3mi | AP7: Open span | AQ7: Good 8-15k | AS7: =ROUND(INDEX('Scoring Method'!$B$63:$B$70,MATCH(AE7,'Scoring Method'!$A$63:$A$70,0))*0.625+INDEX('Scoring Method'!$B$105:$B$113,MATCH(AP7,'Scoring Method'!$A$105:$A$113,0))+INDEX('Scoring Method'!$B$74:$B$78,MATCH(AQ7,'Scoring Method'!$A$74:$A$78,0))*0.6667+INDEX('Scoring Method'!$B$96:$B$101,MATCH(AO7,'Scoring Method'!$A$96:$A$101,0))+INDEX('Scoring Method'!$B$343:$B$347,MATCH(X7,'Scoring Method'!$A$343:$A$347,0))*0.3333+INDEX('Scoring Method'!$B$25:$B$27,MATCH(P7,'Scoring Method'!$A$25:$A$27,0))*0.3333,1) | AT7: =AS7*U7/100 | AU7: Latonia | AV7: 78 | AW7: Sourced | AX7: Safe 70-79 | AY7: =ROUND(INDEX('Scoring Method'!$B$132:$B$140,MATCH(AE7,'Scoring Method'!$A$132:$A$140,0))+INDEX('Scoring Method'!$B$144:$B$152,MATCH(AP7,'Scoring Method'!$A$144:$A$152,0))+INDEX('Scoring Method'!$B$156:$B$160,MATCH(AQ7,'Scoring Method'!$A$156:$A$160,0))+INDEX('Scoring Method'!$B$164:$B$169,MATCH(AO7,'Scoring Method'!$A$164:$A$169,0))+INDEX('Scoring Method'!$B$173:$B$178,MATCH(AX7,'Scoring Method'!$A$173:$A$178,0))+INDEX('Scoring Method'!$B$349:$B$353,MATCH(X7,'Scoring Method'!$A$349:$A$353,0))+INDEX('Scoring Method'!$B$188:$B$190,MATCH(P7,'Scoring Method'!$A$188:$A$190,0)),1) | AZ7: =AY7*U7/100 | BA7: No chain signal | BB7: 1 | BC7: Right-sized 0.35-0.75 AC | BD7: 1 | BE7: =ROUND(INDEX('Scoring Method'!$B$268:$B$276,MATCH(AE7,'Scoring Method'!$A$268:$A$276,0))+INDEX('Scoring Method'!$B$280:$B$288,MATCH(AP7,'Scoring Method'!$A$280:$A$288,0))+INDEX('Scoring Method'!$B$292:$B$296,MATCH(AQ7,'Scoring Method'!$A$292:$A$296,0))+INDEX('Scoring Method'!$B$300:$B$305,MATCH(AO7,'Scoring Method'!$A$300:$A$305,0))+INDEX('Scoring Method'!$B$309:$B$314,MATCH(AX7,'Scoring Method'!$A$309:$A$314,0))+INDEX('Scoring Method'!$B$337:$B$341,MATCH(X7,'Scoring Method'!$A$337:$A$341,0))+INDEX('Scoring Method'!$B$324:$B$326,MATCH(P7,'Scoring Method'!$A$324:$A$326,0)),1) | BF7: =ROUND(INDEX('Scoring Method'!$B$268:$B$276,MATCH(AE7,'Scoring Method'!$A$268:$A$276,0))*BB7*BD7+INDEX('Scoring Method'!$B$280:$B$288,MATCH(AP7,'Scoring Method'!$A$280:$A$288,0))*BM7*BB7*BD7+INDEX('Scoring Method'!$B$292:$B$296,MATCH(AQ7,'Scoring Method'!$A$292:$A$296,0))*BD7+INDEX('Scoring Method'!$B$300:$B$305,MATCH(AO7,'Scoring Method'!$A$300:$A$305,0))*BM7*BB7+INDEX('Scoring Method'!$B$309:$B$314,MATCH(AX7,'Scoring Method'!$A$309:$A$314,0))+INDEX('Scoring Method'!$B$337:$B$341,MATCH(X7,'Scoring Method'!$A$337:$A$341,0))+INDEX('Scoring Method'!$B$324:$B$326,MATCH(P7,'Scoring Method'!$A$324:$A$326,0)),1) | BG7: Fits (~$4,684/mo) | BH7: GI | BI7: General Industrial | BL7: No path | BM7: =INDEX('Scoring Method'!$B$358:$B$363,MATCH(BL7,'Scoring Method'!$A$358:$A$363,0))
A8: 7 | B8: 056-11-09-003.00 | C8: 3022 MADISON AVE | D8: JCR INVESTMENTS LLC | E8: 9455 TEBBS CT | F8: HARRISON | G8: OH | H8: LAUNDROMAT | I8: 20578 | J8: =I8/43560 | K8: 605.9 | L8: =I8/(K8^2) | M8: Ideal 18-32k | N8: C | O8: Compact >=.055 | P8: Low | Q8: Out-of-state | R8: Passive vehicle | S8: 1 | T8: =INDEX('Scoring Method'!$B$6:$B$9,MATCH(M8,'Scoring Method'!$A$6:$A$9,0))+INDEX('Scoring Method'!$B$12:$B$16,MATCH(N8,'Scoring Method'!$A$12:$A$16,0))+INDEX('Scoring Method'!$B$19:$B$22,MATCH(O8,'Scoring Method'!$A$19:$A$22,0))+INDEX('Scoring Method'!$B$25:$B$27,MATCH(P8,'Scoring Method'!$A$25:$A$27,0)) | U8: =(INDEX('Scoring Method'!$B$30:$B$33,MATCH(Q8,'Scoring Method'!$A$30:$A$33,0))+INDEX('Scoring Method'!$B$36:$B$42,MATCH(R8,'Scoring Method'!$A$36:$A$42,0))+INDEX('Scoring Method'!$B$45:$B$47,MATCH(IF(S8=1,"1",IF(S8=2,"2","3+")),'Scoring Method'!$A$45:$A$47,0)))/90*100 | V8: =T8*U8/100 | W8: 2300 | X8: X (minimal hazard) | Y8: 17650 | Z8: =W8/I8 | AA8: =MAX(0,(Y8-5000)/300) | AC8: 0.45 | AD8: ok | AE8: Target 1.5-2.5k | AF8: =INDEX('Scoring Method'!$B$63:$B$71,MATCH(AE8,'Scoring Method'!$A$63:$A$71,0))+INDEX('Scoring Method'!$B$75:$B$79,MATCH("Ample >=15k",'Scoring Method'!$A$75:$A$79,0))+INDEX('Scoring Method'!$B$343:$B$347,MATCH(X8,'Scoring Method'!$A$343:$A$347,0))+INDEX('Scoring Method'!$B$25:$B$27,MATCH(P8,'Scoring Method'!$A$25:$A$27,0)) | AG8: =AF8*U8/100 | AH8: LINK-GIS + LoopNet | AI8: 39.05255 | AJ8: -84.51619 | AK8: 2.2 | AL8: 2.68 | AM8: 3.39 | AN8: 2.19 | AO8: Distant 2-3mi | AP8: Retail shell | AQ8: Ample >=15k | AS8: =ROUND(INDEX('Scoring Method'!$B$63:$B$70,MATCH(AE8,'Scoring Method'!$A$63:$A$70,0))*0.625+INDEX('Scoring Method'!$B$105:$B$113,MATCH(AP8,'Scoring Method'!$A$105:$A$113,0))+INDEX('Scoring Method'!$B$74:$B$78,MATCH(AQ8,'Scoring Method'!$A$74:$A$78,0))*0.6667+INDEX('Scoring Method'!$B$96:$B$101,MATCH(AO8,'Scoring Method'!$A$96:$A$101,0))+INDEX('Scoring Method'!$B$343:$B$347,MATCH(X8,'Scoring Method'!$A$343:$A$347,0))*0.3333+INDEX('Scoring Method'!$B$25:$B$27,MATCH(P8,'Scoring Method'!$A$25:$A$27,0))*0.3333,1) | AT8: =AS8*U8/100 | AU8: Latonia Rosedale | AV8: 68 | AW8: Sourced | AX8: Moderate 60-69 | AY8: =ROUND(INDEX('Scoring Method'!$B$132:$B$140,MATCH(AE8,'Scoring Method'!$A$132:$A$140,0))+INDEX('Scoring Method'!$B$144:$B$152,MATCH(AP8,'Scoring Method'!$A$144:$A$152,0))+INDEX('Scoring Method'!$B$156:$B$160,MATCH(AQ8,'Scoring Method'!$A$156:$A$160,0))+INDEX('Scoring Method'!$B$164:$B$169,MATCH(AO8,'Scoring Method'!$A$164:$A$169,0))+INDEX('Scoring Method'!$B$173:$B$178,MATCH(AX8,'Scoring Method'!$A$173:$A$178,0))+INDEX('Scoring Method'!$B$349:$B$353,MATCH(X8,'Scoring Method'!$A$349:$A$353,0))+INDEX('Scoring Method'!$B$188:$B$190,MATCH(P8,'Scoring Method'!$A$188:$A$190,0)),1) | AZ8: =AY8*U8/100 | BA8: No chain signal | BB8: 1 | BC8: Right-sized 0.35-0.75 AC | BD8: 1 | BE8: =ROUND(INDEX('Scoring Method'!$B$268:$B$276,MATCH(AE8,'Scoring Method'!$A$268:$A$276,0))+INDEX('Scoring Method'!$B$280:$B$288,MATCH(AP8,'Scoring Method'!$A$280:$A$288,0))+INDEX('Scoring Method'!$B$292:$B$296,MATCH(AQ8,'Scoring Method'!$A$292:$A$296,0))+INDEX('Scoring Method'!$B$300:$B$305,MATCH(AO8,'Scoring Method'!$A$300:$A$305,0))+INDEX('Scoring Method'!$B$309:$B$314,MATCH(AX8,'Scoring Method'!$A$309:$A$314,0))+INDEX('Scoring Method'!$B$337:$B$341,MATCH(X8,'Scoring Method'!$A$337:$A$341,0))+INDEX('Scoring Method'!$B$324:$B$326,MATCH(P8,'Scoring Method'!$A$324:$A$326,0)),1) | BF8: =ROUND(INDEX('Scoring Method'!$B$268:$B$276,MATCH(AE8,'Scoring Method'!$A$268:$A$276,0))*BB8*BD8+INDEX('Scoring Method'!$B$280:$B$288,MATCH(AP8,'Scoring Method'!$A$280:$A$288,0))*BM8*BB8*BD8+INDEX('Scoring Method'!$B$292:$B$296,MATCH(AQ8,'Scoring Method'!$A$292:$A$296,0))*BD8+INDEX('Scoring Method'!$B$300:$B$305,MATCH(AO8,'Scoring Method'!$A$300:$A$305,0))*BM8*BB8+INDEX('Scoring Method'!$B$309:$B$314,MATCH(AX8,'Scoring Method'!$A$309:$A$314,0))+INDEX('Scoring Method'!$B$337:$B$341,MATCH(X8,'Scoring Method'!$A$337:$A$341,0))+INDEX('Scoring Method'!$B$324:$B$326,MATCH(P8,'Scoring Method'!$A$324:$A$326,0)),1) | BG8: Fits (~$2,108/mo) | BH8: SU | BI8: Semi-Urban Residential | BL8: SU corner unverified | BM8: =INDEX('Scoring Method'!$B$358:$B$363,MATCH(BL8,'Scoring Method'!$A$358:$A$363,0))
A9: 8 | B9: 040-34-06-001.02 | C9: 316 PHILADELPHIA ST | D9: CURTIS JAMES INVESTMENTS | E9: PO BOX 6969 | F9: SYRACUSE | G9: NY | H9: FAST FOOD-DRIVE THRU REST | I9: 29874 | J9: =I9/43560 | K9: 692 | L9: =I9/(K9^2) | M9: Ideal 18-32k | N9: C | O9: Compact >=.055 | P9: Low | Q9: Out-of-state | R9: Passive vehicle | S9: 1 | T9: =INDEX('Scoring Method'!$B$6:$B$9,MATCH(M9,'Scoring Method'!$A$6:$A$9,0))+INDEX('Scoring Method'!$B$12:$B$16,MATCH(N9,'Scoring Method'!$A$12:$A$16,0))+INDEX('Scoring Method'!$B$19:$B$22,MATCH(O9,'Scoring Method'!$A$19:$A$22,0))+INDEX('Scoring Method'!$B$25:$B$27,MATCH(P9,'Scoring Method'!$A$25:$A$27,0)) | U9: =(INDEX('Scoring Method'!$B$30:$B$33,MATCH(Q9,'Scoring Method'!$A$30:$A$33,0))+INDEX('Scoring Method'!$B$36:$B$42,MATCH(R9,'Scoring Method'!$A$36:$A$42,0))+INDEX('Scoring Method'!$B$45:$B$47,MATCH(IF(S9=1,"1",IF(S9=2,"2","3+")),'Scoring Method'!$A$45:$A$47,0)))/90*100 | V9: =T9*U9/100 | W9: 2759 | X9: X (levee-protected) | Y9: 25925 | Z9: =W9/I9 | AA9: =MAX(0,(Y9-5000)/300) | AC9: 0.69 | AD9: ok | AE9: Above 2.5-4k | AF9: =INDEX('Scoring Method'!$B$63:$B$71,MATCH(AE9,'Scoring Method'!$A$63:$A$71,0))+INDEX('Scoring Method'!$B$75:$B$79,MATCH("Ample >=15k",'Scoring Method'!$A$75:$A$79,0))+INDEX('Scoring Method'!$B$343:$B$347,MATCH(X9,'Scoring Method'!$A$343:$A$347,0))+INDEX('Scoring Method'!$B$25:$B$27,MATCH(P9,'Scoring Method'!$A$25:$A$27,0)) | AG9: =AF9*U9/100 | AH9: LINK-GIS + LoopNet | AI9: 39.08678 | AJ9: -84.51954 | AK9: 0.19 | AL9: 0.66 | AM9: 1.09 | AN9: 0.19 | AO9: Core <=0.35mi | AP9: Built-out kitchen | AQ9: Ample >=15k | AS9: =ROUND(INDEX('Scoring Method'!$B$63:$B$70,MATCH(AE9,'Scoring Method'!$A$63:$A$70,0))*0.625+INDEX('Scoring Method'!$B$105:$B$113,MATCH(AP9,'Scoring Method'!$A$105:$A$113,0))+INDEX('Scoring Method'!$B$74:$B$78,MATCH(AQ9,'Scoring Method'!$A$74:$A$78,0))*0.6667+INDEX('Scoring Method'!$B$96:$B$101,MATCH(AO9,'Scoring Method'!$A$96:$A$101,0))+INDEX('Scoring Method'!$B$343:$B$347,MATCH(X9,'Scoring Method'!$A$343:$A$347,0))*0.3333+INDEX('Scoring Method'!$B$25:$B$27,MATCH(P9,'Scoring Method'!$A$25:$A$27,0))*0.3333,1) | AT9: =AS9*U9/100 | AU9: Botany Hills / Riverfront West | AV9: 45 | AW9: ESTIMATED | AX9: Mixed 45-59 | AY9: =ROUND(INDEX('Scoring Method'!$B$132:$B$140,MATCH(AE9,'Scoring Method'!$A$132:$A$140,0))+INDEX('Scoring Method'!$B$144:$B$152,MATCH(AP9,'Scoring Method'!$A$144:$A$152,0))+INDEX('Scoring Method'!$B$156:$B$160,MATCH(AQ9,'Scoring Method'!$A$156:$A$160,0))+INDEX('Scoring Method'!$B$164:$B$169,MATCH(AO9,'Scoring Method'!$A$164:$A$169,0))+INDEX('Scoring Method'!$B$173:$B$178,MATCH(AX9,'Scoring Method'!$A$173:$A$178,0))+INDEX('Scoring Method'!$B$349:$B$353,MATCH(X9,'Scoring Method'!$A$349:$A$353,0))+INDEX('Scoring Method'!$B$188:$B$190,MATCH(P9,'Scoring Method'!$A$188:$A$190,0)),1) | AZ9: =AY9*U9/100 | BA9: Chain format + investor | BB9: 0.45 | BC9: Right-sized 0.35-0.75 AC | BD9: 1 | BE9: =ROUND(INDEX('Scoring Method'!$B$268:$B$276,MATCH(AE9,'Scoring Method'!$A$268:$A$276,0))+INDEX('Scoring Method'!$B$280:$B$288,MATCH(AP9,'Scoring Method'!$A$280:$A$288,0))+INDEX('Scoring Method'!$B$292:$B$296,MATCH(AQ9,'Scoring Method'!$A$292:$A$296,0))+INDEX('Scoring Method'!$B$300:$B$305,MATCH(AO9,'Scoring Method'!$A$300:$A$305,0))+INDEX('Scoring Method'!$B$309:$B$314,MATCH(AX9,'Scoring Method'!$A$309:$A$314,0))+INDEX('Scoring Method'!$B$337:$B$341,MATCH(X9,'Scoring Method'!$A$337:$A$341,0))+INDEX('Scoring Method'!$B$324:$B$326,MATCH(P9,'Scoring Method'!$A$324:$A$326,0)),1) | BF9: =ROUND(INDEX('Scoring Method'!$B$268:$B$276,MATCH(AE9,'Scoring Method'!$A$268:$A$276,0))*BB9*BD9+INDEX('Scoring Method'!$B$280:$B$288,MATCH(AP9,'Scoring Method'!$A$280:$A$288,0))*BM9*BB9*BD9+INDEX('Scoring Method'!$B$292:$B$296,MATCH(AQ9,'Scoring Method'!$A$292:$A$296,0))*BD9+INDEX('Scoring Method'!$B$300:$B$305,MATCH(AO9,'Scoring Method'!$A$300:$A$305,0))*BM9*BB9+INDEX('Scoring Method'!$B$309:$B$314,MATCH(AX9,'Scoring Method'!$A$309:$A$314,0))+INDEX('Scoring Method'!$B$337:$B$341,MATCH(X9,'Scoring Method'!$A$337:$A$341,0))+INDEX('Scoring Method'!$B$324:$B$326,MATCH(P9,'Scoring Method'!$A$324:$A$326,0)),1) | BG9: Fits (~$2,529/mo) | BH9: AUC | BI9: Auto-Urban Commercial | BL9: Bar permitted | BM9: =INDEX('Scoring Method'!$B$358:$B$363,MATCH(BL9,'Scoring Method'!$A$358:$A$363,0))
A10: 9 | B10: 055-20-00-002.00 | C10: 2601 BENTON RD | D10: TIBTANI HICHAM & | E10: NO KNOWN ADDRESS | H10: CONVENIENCE STORE | I10: 18193 | J10: =I10/43560 | K10: 586 | L10: =I10/(K10^2) | M10: Ideal 18-32k | N10: C | O10: Regular .045-.055 | P10: Low | Q10: Out-of-state | R10: Individual | S10: 1 | T10: =INDEX('Scoring Method'!$B$6:$B$9,MATCH(M10,'Scoring Method'!$A$6:$A$9,0))+INDEX('Scoring Method'!$B$12:$B$16,MATCH(N10,'Scoring Method'!$A$12:$A$16,0))+INDEX('Scoring Method'!$B$19:$B$22,MATCH(O10,'Scoring Method'!$A$19:$A$22,0))+INDEX('Scoring Method'!$B$25:$B$27,MATCH(P10,'Scoring Method'!$A$25:$A$27,0)) | U10: =(INDEX('Scoring Method'!$B$30:$B$33,MATCH(Q10,'Scoring Method'!$A$30:$A$33,0))+INDEX('Scoring Method'!$B$36:$B$42,MATCH(R10,'Scoring Method'!$A$36:$A$42,0))+INDEX('Scoring Method'!$B$45:$B$47,MATCH(IF(S10=1,"1",IF(S10=2,"2","3+")),'Scoring Method'!$A$45:$A$47,0)))/90*100 | V10: =T10*U10/100 | W10: 4000 | X10: X (minimal hazard) | Y10: 11375 | Z10: =W10/I10 | AA10: =MAX(0,(Y10-5000)/300) | AC10: 0.33 | AD10: ok | AE10: Above 2.5-4k | AF10: =INDEX('Scoring Method'!$B$63:$B$71,MATCH(AE10,'Scoring Method'!$A$63:$A$71,0))+INDEX('Scoring Method'!$B$75:$B$79,MATCH("Good 8-15k",'Scoring Method'!$A$75:$A$79,0))+INDEX('Scoring Method'!$B$343:$B$347,MATCH(X10,'Scoring Method'!$A$343:$A$347,0))+INDEX('Scoring Method'!$B$25:$B$27,MATCH(P10,'Scoring Method'!$A$25:$A$27,0)) | AG10: =AF10*U10/100 | AH10: LINK-GIS + LoopNet | AI10: 39.05758 | AJ10: -84.51356 | AK10: 1.87 | AL10: 2.32 | AM10: 3.04 | AN10: 1.83 | AO10: Outer 1.25-2mi | AP10: Built-out kitchen | AQ10: Good 8-15k | AS10: =ROUND(INDEX('Scoring Method'!$B$63:$B$70,MATCH(AE10,'Scoring Method'!$A$63:$A$70,0))*0.625+INDEX('Scoring Method'!$B$105:$B$113,MATCH(AP10,'Scoring Method'!$A$105:$A$113,0))+INDEX('Scoring Method'!$B$74:$B$78,MATCH(AQ10,'Scoring Method'!$A$74:$A$78,0))*0.6667+INDEX('Scoring Method'!$B$96:$B$101,MATCH(AO10,'Scoring Method'!$A$96:$A$101,0))+INDEX('Scoring Method'!$B$343:$B$347,MATCH(X10,'Scoring Method'!$A$343:$A$347,0))*0.3333+INDEX('Scoring Method'!$B$25:$B$27,MATCH(P10,'Scoring Method'!$A$25:$A$27,0))*0.3333,1) | AT10: =AS10*U10/100 | AU10: Latonia Rosedale | AV10: 68 | AW10: Sourced | AX10: Moderate 60-69 | AY10: =ROUND(INDEX('Scoring Method'!$B$132:$B$140,MATCH(AE10,'Scoring Method'!$A$132:$A$140,0))+INDEX('Scoring Method'!$B$144:$B$152,MATCH(AP10,'Scoring Method'!$A$144:$A$152,0))+INDEX('Scoring Method'!$B$156:$B$160,MATCH(AQ10,'Scoring Method'!$A$156:$A$160,0))+INDEX('Scoring Method'!$B$164:$B$169,MATCH(AO10,'Scoring Method'!$A$164:$A$169,0))+INDEX('Scoring Method'!$B$173:$B$178,MATCH(AX10,'Scoring Method'!$A$173:$A$178,0))+INDEX('Scoring Method'!$B$349:$B$353,MATCH(X10,'Scoring Method'!$A$349:$A$353,0))+INDEX('Scoring Method'!$B$188:$B$190,MATCH(P10,'Scoring Method'!$A$188:$A$190,0)),1) | AZ10: =AY10*U10/100 | BA10: Chain format + local owner | BB10: 0.7 | BC10: Right-sized 0.35-0.75 AC | BD10: 1 | BE10: =ROUND(INDEX('Scoring Method'!$B$268:$B$276,MATCH(AE10,'Scoring Method'!$A$268:$A$276,0))+INDEX('Scoring Method'!$B$280:$B$288,MATCH(AP10,'Scoring Method'!$A$280:$A$288,0))+INDEX('Scoring Method'!$B$292:$B$296,MATCH(AQ10,'Scoring Method'!$A$292:$A$296,0))+INDEX('Scoring Method'!$B$300:$B$305,MATCH(AO10,'Scoring Method'!$A$300:$A$305,0))+INDEX('Scoring Method'!$B$309:$B$314,MATCH(AX10,'Scoring Method'!$A$309:$A$314,0))+INDEX('Scoring Method'!$B$337:$B$341,MATCH(X10,'Scoring Method'!$A$337:$A$341,0))+INDEX('Scoring Method'!$B$324:$B$326,MATCH(P10,'Scoring Method'!$A$324:$A$326,0)),1) | BF10: =ROUND(INDEX('Scoring Method'!$B$268:$B$276,MATCH(AE10,'Scoring Method'!$A$268:$A$276,0))*BB10*BD10+INDEX('Scoring Method'!$B$280:$B$288,MATCH(AP10,'Scoring Method'!$A$280:$A$288,0))*BM10*BB10*BD10+INDEX('Scoring Method'!$B$292:$B$296,MATCH(AQ10,'Scoring Method'!$A$292:$A$296,0))*BD10+INDEX('Scoring Method'!$B$300:$B$305,MATCH(AO10,'Scoring Method'!$A$300:$A$305,0))*BM10*BB10+INDEX('Scoring Method'!$B$309:$B$314,MATCH(AX10,'Scoring Method'!$A$309:$A$314,0))+INDEX('Scoring Method'!$B$337:$B$341,MATCH(X10,'Scoring Method'!$A$337:$A$341,0))+INDEX('Scoring Method'!$B$324:$B$326,MATCH(P10,'Scoring Method'!$A$324:$A$326,0)),1) | BG10: Fits (~$3,667/mo) | BH10: SU | BI10: Semi-Urban Residential | BL10: SU corner unverified | BM10: =INDEX('Scoring Method'!$B$358:$B$363,MATCH(BL10,'Scoring Method'!$A$358:$A$363,0))
A11: 10 | B11: 042-30-00-039.00 | C11: 3296 MADISON PIKE | D11: SCHLIPF DANIEL W | E11: 3197 HIGH RIDGE DR | F11: TAYLOR MILL | G11: KY | H11: AUTO SERVICE/REPAIR | I11: 23623 | J11: =I11/43560 | K11: 693.4 | L11: =I11/(K11^2) | M11: Ideal 18-32k | N11: A | O11: Regular .045-.055 | P11: Moderate | Q11: Out-of-city KY | R11: Individual | S11: 1 | T11: =INDEX('Scoring Method'!$B$6:$B$9,MATCH(M11,'Scoring Method'!$A$6:$A$9,0))+INDEX('Scoring Method'!$B$12:$B$16,MATCH(N11,'Scoring Method'!$A$12:$A$16,0))+INDEX('Scoring Method'!$B$19:$B$22,MATCH(O11,'Scoring Method'!$A$19:$A$22,0))+INDEX('Scoring Method'!$B$25:$B$27,MATCH(P11,'Scoring Method'!$A$25:$A$27,0)) | U11: =(INDEX('Scoring Method'!$B$30:$B$33,MATCH(Q11,'Scoring Method'!$A$30:$A$33,0))+INDEX('Scoring Method'!$B$36:$B$42,MATCH(R11,'Scoring Method'!$A$36:$A$42,0))+INDEX('Scoring Method'!$B$45:$B$47,MATCH(IF(S11=1,"1",IF(S11=2,"2","3+")),'Scoring Method'!$A$45:$A$47,0)))/90*100 | V11: =T11*U11/100 | W11: 4467 | X11: X shaded (0.2%) | Y11: 18825 | Z11: =W11/I11 | AA11: =MAX(0,(Y11-5000)/300) | AC11: 0.59 | AD11: ok | AE11: Large 4-6k | AF11: =INDEX('Scoring Method'!$B$63:$B$71,MATCH(AE11,'Scoring Method'!$A$63:$A$71,0))+INDEX('Scoring Method'!$B$75:$B$79,MATCH("Ample >=15k",'Scoring Method'!$A$75:$A$79,0))+INDEX('Scoring Method'!$B$343:$B$347,MATCH(X11,'Scoring Method'!$A$343:$A$347,0))+INDEX('Scoring Method'!$B$25:$B$27,MATCH(P11,'Scoring Method'!$A$25:$A$27,0)) | AG11: =AF11*U11/100 | AH11: LINK-GIS + LoopNet | AI11: 39.04224 | AJ11: -84.52584 | AK11: 2.94 | AL11: 3.49 | AM11: 4.16 | AN11: 2.94 | AO11: Distant 2-3mi | AP11: Open span | AQ11: Ample >=15k | AS11: =ROUND(INDEX('Scoring Method'!$B$63:$B$70,MATCH(AE11,'Scoring Method'!$A$63:$A$70,0))*0.625+INDEX('Scoring Method'!$B$105:$B$113,MATCH(AP11,'Scoring Method'!$A$105:$A$113,0))+INDEX('Scoring Method'!$B$74:$B$78,MATCH(AQ11,'Scoring Method'!$A$74:$A$78,0))*0.6667+INDEX('Scoring Method'!$B$96:$B$101,MATCH(AO11,'Scoring Method'!$A$96:$A$101,0))+INDEX('Scoring Method'!$B$343:$B$347,MATCH(X11,'Scoring Method'!$A$343:$A$347,0))*0.3333+INDEX('Scoring Method'!$B$25:$B$27,MATCH(P11,'Scoring Method'!$A$25:$A$27,0))*0.3333,1) | AT11: =AS11*U11/100 | AU11: Rittes East / Winston Park | AV11: 82 | AW11: Sourced | AX11: Very safe 80+ | AY11: =ROUND(INDEX('Scoring Method'!$B$132:$B$140,MATCH(AE11,'Scoring Method'!$A$132:$A$140,0))+INDEX('Scoring Method'!$B$144:$B$152,MATCH(AP11,'Scoring Method'!$A$144:$A$152,0))+INDEX('Scoring Method'!$B$156:$B$160,MATCH(AQ11,'Scoring Method'!$A$156:$A$160,0))+INDEX('Scoring Method'!$B$164:$B$169,MATCH(AO11,'Scoring Method'!$A$164:$A$169,0))+INDEX('Scoring Method'!$B$173:$B$178,MATCH(AX11,'Scoring Method'!$A$173:$A$178,0))+INDEX('Scoring Method'!$B$349:$B$353,MATCH(X11,'Scoring Method'!$A$349:$A$353,0))+INDEX('Scoring Method'!$B$188:$B$190,MATCH(P11,'Scoring Method'!$A$188:$A$190,0)),1) | AZ11: =AY11*U11/100 | BA11: No chain signal | BB11: 1 | BC11: Right-sized 0.35-0.75 AC | BD11: 1 | BE11: =ROUND(INDEX('Scoring Method'!$B$268:$B$276,MATCH(AE11,'Scoring Method'!$A$268:$A$276,0))+INDEX('Scoring Method'!$B$280:$B$288,MATCH(AP11,'Scoring Method'!$A$280:$A$288,0))+INDEX('Scoring Method'!$B$292:$B$296,MATCH(AQ11,'Scoring Method'!$A$292:$A$296,0))+INDEX('Scoring Method'!$B$300:$B$305,MATCH(AO11,'Scoring Method'!$A$300:$A$305,0))+INDEX('Scoring Method'!$B$309:$B$314,MATCH(AX11,'Scoring Method'!$A$309:$A$314,0))+INDEX('Scoring Method'!$B$337:$B$341,MATCH(X11,'Scoring Method'!$A$337:$A$341,0))+INDEX('Scoring Method'!$B$324:$B$326,MATCH(P11,'Scoring Method'!$A$324:$A$326,0)),1) | BF11: =ROUND(INDEX('Scoring Method'!$B$268:$B$276,MATCH(AE11,'Scoring Method'!$A$268:$A$276,0))*BB11*BD11+INDEX('Scoring Method'!$B$280:$B$288,MATCH(AP11,'Scoring Method'!$A$280:$A$288,0))*BM11*BB11*BD11+INDEX('Scoring Method'!$B$292:$B$296,MATCH(AQ11,'Scoring Method'!$A$292:$A$296,0))*BD11+INDEX('Scoring Method'!$B$300:$B$305,MATCH(AO11,'Scoring Method'!$A$300:$A$305,0))*BM11*BB11+INDEX('Scoring Method'!$B$309:$B$314,MATCH(AX11,'Scoring Method'!$A$309:$A$314,0))+INDEX('Scoring Method'!$B$337:$B$341,MATCH(X11,'Scoring Method'!$A$337:$A$341,0))+INDEX('Scoring Method'!$B$324:$B$326,MATCH(P11,'Scoring Method'!$A$324:$A$326,0)),1) | BG11: Fits (~$4,095/mo) | BH11: AUC | BI11: Auto-Urban Commercial | BL11: Bar permitted | BM11: =INDEX('Scoring Method'!$B$358:$B$363,MATCH(BL11,'Scoring Method'!$A$358:$A$363,0))
A12: 11 | B12: 054-22-39-009.00 | C12: 1116 RUSSELL ST | D12: SKLO ACQUISITIONS LLC | E12: PO BOX 172576 | F12: TAMPA | G12: FL | H12: GARAGE | I12: 37630 | J12: =I12/43560 | K12: 776 | L12: =I12/(K12^2) | M12: Near 14-18k/32-45k | N12: A | O12: Compact >=.055 | P12: Moderate | Q12: Out-of-state | R12: Passive vehicle | S12: 1 | T12: =INDEX('Scoring Method'!$B$6:$B$9,MATCH(M12,'Scoring Method'!$A$6:$A$9,0))+INDEX('Scoring Method'!$B$12:$B$16,MATCH(N12,'Scoring Method'!$A$12:$A$16,0))+INDEX('Scoring Method'!$B$19:$B$22,MATCH(O12,'Scoring Method'!$A$19:$A$22,0))+INDEX('Scoring Method'!$B$25:$B$27,MATCH(P12,'Scoring Method'!$A$25:$A$27,0)) | U12: =(INDEX('Scoring Method'!$B$30:$B$33,MATCH(Q12,'Scoring Method'!$A$30:$A$33,0))+INDEX('Scoring Method'!$B$36:$B$42,MATCH(R12,'Scoring Method'!$A$36:$A$42,0))+INDEX('Scoring Method'!$B$45:$B$47,MATCH(IF(S12=1,"1",IF(S12=2,"2","3+")),'Scoring Method'!$A$45:$A$47,0)))/90*100 | V12: =T12*U12/100 | W12: 21500 | X12: X (minimal hazard) | Y12: 13525 | Z12: =W12/I12 | AA12: =MAX(0,(Y12-5000)/300) | AC12: 0.86 | AD12: ok | AE12: Far oversize >12k | AF12: =INDEX('Scoring Method'!$B$63:$B$71,MATCH(AE12,'Scoring Method'!$A$63:$A$71,0))+INDEX('Scoring Method'!$B$75:$B$79,MATCH("Good 8-15k",'Scoring Method'!$A$75:$A$79,0))+INDEX('Scoring Method'!$B$343:$B$347,MATCH(X12,'Scoring Method'!$A$343:$A$347,0))+INDEX('Scoring Method'!$B$25:$B$27,MATCH(P12,'Scoring Method'!$A$25:$A$27,0)) | AG12: =AF12*U12/100 | AH12: LINK-GIS + LoopNet | AI12: 39.07773 | AJ12: -84.51152 | AK12: 0.57 | AL12: 0.92 | AM12: 1.64 | AN12: 0.43 | AO12: Near 0.35-0.75mi | AP12: Open span | AQ12: Good 8-15k | AS12: =ROUND(INDEX('Scoring Method'!$B$63:$B$70,MATCH(AE12,'Scoring Method'!$A$63:$A$70,0))*0.625+INDEX('Scoring Method'!$B$105:$B$113,MATCH(AP12,'Scoring Method'!$A$105:$A$113,0))+INDEX('Scoring Method'!$B$74:$B$78,MATCH(AQ12,'Scoring Method'!$A$74:$A$78,0))*0.6667+INDEX('Scoring Method'!$B$96:$B$101,MATCH(AO12,'Scoring Method'!$A$96:$A$101,0))+INDEX('Scoring Method'!$B$343:$B$347,MATCH(X12,'Scoring Method'!$A$343:$A$347,0))*0.3333+INDEX('Scoring Method'!$B$25:$B$27,MATCH(P12,'Scoring Method'!$A$25:$A$27,0))*0.3333,1) | AT12: =AS12*U12/100 | AU12: Old Seminary Square | AV12: 35 | AW12: ESTIMATED | AX12: Elevated 35-44 | AY12: =ROUND(INDEX('Scoring Method'!$B$132:$B$140,MATCH(AE12,'Scoring Method'!$A$132:$A$140,0))+INDEX('Scoring Method'!$B$144:$B$152,MATCH(AP12,'Scoring Method'!$A$144:$A$152,0))+INDEX('Scoring Method'!$B$156:$B$160,MATCH(AQ12,'Scoring Method'!$A$156:$A$160,0))+INDEX('Scoring Method'!$B$164:$B$169,MATCH(AO12,'Scoring Method'!$A$164:$A$169,0))+INDEX('Scoring Method'!$B$173:$B$178,MATCH(AX12,'Scoring Method'!$A$173:$A$178,0))+INDEX('Scoring Method'!$B$349:$B$353,MATCH(X12,'Scoring Method'!$A$349:$A$353,0))+INDEX('Scoring Method'!$B$188:$B$190,MATCH(P12,'Scoring Method'!$A$188:$A$190,0)),1) | AZ12: =AY12*U12/100 | BA12: No chain signal | BB12: 1 | BC12: Large 0.75-1.25 AC | BD12: 0.9 | BE12: =ROUND(INDEX('Scoring Method'!$B$268:$B$276,MATCH(AE12,'Scoring Method'!$A$268:$A$276,0))+INDEX('Scoring Method'!$B$280:$B$288,MATCH(AP12,'Scoring Method'!$A$280:$A$288,0))+INDEX('Scoring Method'!$B$292:$B$296,MATCH(AQ12,'Scoring Method'!$A$292:$A$296,0))+INDEX('Scoring Method'!$B$300:$B$305,MATCH(AO12,'Scoring Method'!$A$300:$A$305,0))+INDEX('Scoring Method'!$B$309:$B$314,MATCH(AX12,'Scoring Method'!$A$309:$A$314,0))+INDEX('Scoring Method'!$B$337:$B$341,MATCH(X12,'Scoring Method'!$A$337:$A$341,0))+INDEX('Scoring Method'!$B$324:$B$326,MATCH(P12,'Scoring Method'!$A$324:$A$326,0)),1) | BF12: =ROUND(INDEX('Scoring Method'!$B$268:$B$276,MATCH(AE12,'Scoring Method'!$A$268:$A$276,0))*BB12*BD12+INDEX('Scoring Method'!$B$280:$B$288,MATCH(AP12,'Scoring Method'!$A$280:$A$288,0))*BM12*BB12*BD12+INDEX('Scoring Method'!$B$292:$B$296,MATCH(AQ12,'Scoring Method'!$A$292:$A$296,0))*BD12+INDEX('Scoring Method'!$B$300:$B$305,MATCH(AO12,'Scoring Method'!$A$300:$A$305,0))*BM12*BB12+INDEX('Scoring Method'!$B$309:$B$314,MATCH(AX12,'Scoring Method'!$A$309:$A$314,0))+INDEX('Scoring Method'!$B$337:$B$341,MATCH(X12,'Scoring Method'!$A$337:$A$341,0))+INDEX('Scoring Method'!$B$324:$B$326,MATCH(P12,'Scoring Method'!$A$324:$A$326,0)),1) | BG12: Over (~$19,708/mo) | BH12: TUMU (TS) | BI12: Traditional Urban Mixed Use | BK12: Yes | BL12: Bar permitted | BM12: =INDEX('Scoring Method'!$B$358:$B$363,MATCH(BL12,'Scoring Method'!$A$358:$A$363,0))
A13: 12 | B13: 054-23-04-012.00 | C13: 423 SCOTT ST | D13: DECASTRO MANAGEMENT LLC | E13: 700 WALNUT ST STE 311 | F13: CINCINNATI | G13: OH | H13: AUTO SERVICE/REPAIR | I13: 36100 | J13: =I13/43560 | K13: 760 | L13: =I13/(K13^2) | M13: Near 14-18k/32-45k | N13: A | O13: Compact >=.055 | P13: Moderate | Q13: Out-of-state | R13: Passive vehicle | S13: 1 | T13: =INDEX('Scoring Method'!$B$6:$B$9,MATCH(M13,'Scoring Method'!$A$6:$A$9,0))+INDEX('Scoring Method'!$B$12:$B$16,MATCH(N13,'Scoring Method'!$A$12:$A$16,0))+INDEX('Scoring Method'!$B$19:$B$22,MATCH(O13,'Scoring Method'!$A$19:$A$22,0))+INDEX('Scoring Method'!$B$25:$B$27,MATCH(P13,'Scoring Method'!$A$25:$A$27,0)) | U13: =(INDEX('Scoring Method'!$B$30:$B$33,MATCH(Q13,'Scoring Method'!$A$30:$A$33,0))+INDEX('Scoring Method'!$B$36:$B$42,MATCH(R13,'Scoring Method'!$A$36:$A$42,0))+INDEX('Scoring Method'!$B$45:$B$47,MATCH(IF(S13=1,"1",IF(S13=2,"2","3+")),'Scoring Method'!$A$45:$A$47,0)))/90*100 | V13: =T13*U13/100 | W13: 17586 | X13: X (minimal hazard) | Y13: 17825 | Z13: =W13/I13 | AA13: =MAX(0,(Y13-5000)/300) | AC13: 0.83 | AD13: ok | AE13: Far oversize >12k | AF13: =INDEX('Scoring Method'!$B$63:$B$71,MATCH(AE13,'Scoring Method'!$A$63:$A$71,0))+INDEX('Scoring Method'!$B$75:$B$79,MATCH("Ample >=15k",'Scoring Method'!$A$75:$A$79,0))+INDEX('Scoring Method'!$B$343:$B$347,MATCH(X13,'Scoring Method'!$A$343:$A$347,0))+INDEX('Scoring Method'!$B$25:$B$27,MATCH(P13,'Scoring Method'!$A$25:$A$27,0)) | AG13: =AF13*U13/100 | AH13: LINK-GIS + LoopNet | AI13: 39.08638 | AJ13: -84.50972 | AK13: 0.46 | AL13: 0.32 | AM13: 1.05 | AN13: 0.18 | AO13: Core <=0.35mi | AP13: Open span | AQ13: Ample >=15k | AS13: =ROUND(INDEX('Scoring Method'!$B$63:$B$70,MATCH(AE13,'Scoring Method'!$A$63:$A$70,0))*0.625+INDEX('Scoring Method'!$B$105:$B$113,MATCH(AP13,'Scoring Method'!$A$105:$A$113,0))+INDEX('Scoring Method'!$B$74:$B$78,MATCH(AQ13,'Scoring Method'!$A$74:$A$78,0))*0.6667+INDEX('Scoring Method'!$B$96:$B$101,MATCH(AO13,'Scoring Method'!$A$96:$A$101,0))+INDEX('Scoring Method'!$B$343:$B$347,MATCH(X13,'Scoring Method'!$A$343:$A$347,0))*0.3333+INDEX('Scoring Method'!$B$25:$B$27,MATCH(P13,'Scoring Method'!$A$25:$A$27,0))*0.3333,1) | AT13: =AS13*U13/100 | AU13: Central Business District | AV13: 48 | AW13: ESTIMATED | AX13: Mixed 45-59 | AY13: =ROUND(INDEX('Scoring Method'!$B$132:$B$140,MATCH(AE13,'Scoring Method'!$A$132:$A$140,0))+INDEX('Scoring Method'!$B$144:$B$152,MATCH(AP13,'Scoring Method'!$A$144:$A$152,0))+INDEX('Scoring Method'!$B$156:$B$160,MATCH(AQ13,'Scoring Method'!$A$156:$A$160,0))+INDEX('Scoring Method'!$B$164:$B$169,MATCH(AO13,'Scoring Method'!$A$164:$A$169,0))+INDEX('Scoring Method'!$B$173:$B$178,MATCH(AX13,'Scoring Method'!$A$173:$A$178,0))+INDEX('Scoring Method'!$B$349:$B$353,MATCH(X13,'Scoring Method'!$A$349:$A$353,0))+INDEX('Scoring Method'!$B$188:$B$190,MATCH(P13,'Scoring Method'!$A$188:$A$190,0)),1) | AZ13: =AY13*U13/100 | BA13: No chain signal | BB13: 1 | BC13: Large 0.75-1.25 AC | BD13: 0.9 | BE13: =ROUND(INDEX('Scoring Method'!$B$268:$B$276,MATCH(AE13,'Scoring Method'!$A$268:$A$276,0))+INDEX('Scoring Method'!$B$280:$B$288,MATCH(AP13,'Scoring Method'!$A$280:$A$288,0))+INDEX('Scoring Method'!$B$292:$B$296,MATCH(AQ13,'Scoring Method'!$A$292:$A$296,0))+INDEX('Scoring Method'!$B$300:$B$305,MATCH(AO13,'Scoring Method'!$A$300:$A$305,0))+INDEX('Scoring Method'!$B$309:$B$314,MATCH(AX13,'Scoring Method'!$A$309:$A$314,0))+INDEX('Scoring Method'!$B$337:$B$341,MATCH(X13,'Scoring Method'!$A$337:$A$341,0))+INDEX('Scoring Method'!$B$324:$B$326,MATCH(P13,'Scoring Method'!$A$324:$A$326,0)),1) | BF13: =ROUND(INDEX('Scoring Method'!$B$268:$B$276,MATCH(AE13,'Scoring Method'!$A$268:$A$276,0))*BB13*BD13+INDEX('Scoring Method'!$B$280:$B$288,MATCH(AP13,'Scoring Method'!$A$280:$A$288,0))*BM13*BB13*BD13+INDEX('Scoring Method'!$B$292:$B$296,MATCH(AQ13,'Scoring Method'!$A$292:$A$296,0))*BD13+INDEX('Scoring Method'!$B$300:$B$305,MATCH(AO13,'Scoring Method'!$A$300:$A$305,0))*BM13*BB13+INDEX('Scoring Method'!$B$309:$B$314,MATCH(AX13,'Scoring Method'!$A$309:$A$314,0))+INDEX('Scoring Method'!$B$337:$B$341,MATCH(X13,'Scoring Method'!$A$337:$A$341,0))+INDEX('Scoring Method'!$B$324:$B$326,MATCH(P13,'Scoring Method'!$A$324:$A$326,0)),1) | BG13: Over (~$16,120/mo) | BH13: DTC (HP) | BI13: Downtown Core | BJ13: HP | BL13: Bar permitted | BM13: =INDEX('Scoring Method'!$B$358:$B$363,MATCH(BL13,'Scoring Method'!$A$358:$A$363,0))
